2025-09-09 10:12:08,368 INFO    MainThread:2818325 [wandb_setup.py:_flush():81] Current SDK version is 0.21.3
2025-09-09 10:12:08,368 INFO    MainThread:2818325 [wandb_setup.py:_flush():81] Configure stats pid to 2818325
2025-09-09 10:12:08,368 INFO    MainThread:2818325 [wandb_setup.py:_flush():81] Loading settings from /home/llmteam/.config/wandb/settings
2025-09-09 10:12:08,368 INFO    MainThread:2818325 [wandb_setup.py:_flush():81] Loading settings from /home/llmteam/qyy/optimizer/nanoGPT/wandb/settings
2025-09-09 10:12:08,368 INFO    MainThread:2818325 [wandb_setup.py:_flush():81] Loading settings from environment variables
2025-09-09 10:12:08,369 INFO    MainThread:2818325 [wandb_init.py:setup_run_log_directory():686] Logging user logs to /home/llmteam/qyy/optimizer/nanoGPT/wandb/run-20250909_101208-mvjmb4to/logs/debug.log
2025-09-09 10:12:08,369 INFO    MainThread:2818325 [wandb_init.py:setup_run_log_directory():687] Logging internal logs to /home/llmteam/qyy/optimizer/nanoGPT/wandb/run-20250909_101208-mvjmb4to/logs/debug-internal.log
2025-09-09 10:12:08,369 INFO    MainThread:2818325 [wandb_init.py:init():813] calling init triggers
2025-09-09 10:12:08,369 INFO    MainThread:2818325 [wandb_init.py:init():818] wandb.init called with sweep_config: {}
config: {'out_dir': 'out_openwebtext', 'eval_interval': 1000, 'log_interval': 10, 'eval_iters': 200, 'eval_only': False, 'always_save_checkpoint': True, 'init_from': 'scratch', 'wandb_log': True, 'wandb_project': 'owt', 'wandb_run_name': 'gpt2-124M', 'dataset': 'openwebtext', 'gradient_accumulation_steps': 40, 'batch_size': 12, 'block_size': 1024, 'n_layer': 12, 'n_head': 12, 'n_embd': 768, 'dropout': 0.0, 'bias': False, 'learning_rate': 0.0006, 'max_iters': 20000, 'weight_decay': 0.1, 'beta1': 0.9, 'beta2': 0.95, 'grad_clip': 1.0, 'decay_lr': True, 'warmup_iters': 2000, 'lr_decay_iters': 20000, 'min_lr': 6e-05, 'backend': 'nccl', 'device': 'cuda', 'dtype': 'bfloat16', 'compile': True, '_wandb': {}}
2025-09-09 10:12:08,369 INFO    MainThread:2818325 [wandb_init.py:init():854] starting backend
2025-09-09 10:12:08,582 INFO    MainThread:2818325 [wandb_init.py:init():857] sending inform_init request
2025-09-09 10:12:08,589 INFO    MainThread:2818325 [wandb_init.py:init():865] backend started and connected
2025-09-09 10:12:08,592 INFO    MainThread:2818325 [wandb_init.py:init():936] updated telemetry
2025-09-09 10:12:08,595 INFO    MainThread:2818325 [wandb_init.py:init():960] communicating run to backend with 90.0 second timeout
2025-09-09 10:12:39,543 INFO    Thread-2 (wrapped_target):2818325 [retry.py:__call__():165] [no run ID] Retry attempt failed:
Traceback (most recent call last):
  File "/home/llmteam/.pyenv/versions/3.11.12/lib/python3.11/site-packages/urllib3/connection.py", line 198, in _new_conn
    sock = connection.create_connection(
           ^^^^^^^^^^^^^^^^^^^^^^^^^^^^^
  File "/home/llmteam/.pyenv/versions/3.11.12/lib/python3.11/site-packages/urllib3/util/connection.py", line 85, in create_connection
    raise err
  File "/home/llmteam/.pyenv/versions/3.11.12/lib/python3.11/site-packages/urllib3/util/connection.py", line 73, in create_connection
    sock.connect(sa)
TimeoutError: timed out

The above exception was the direct cause of the following exception:

Traceback (most recent call last):
  File "/home/llmteam/.pyenv/versions/3.11.12/lib/python3.11/site-packages/urllib3/connectionpool.py", line 787, in urlopen
    response = self._make_request(
               ^^^^^^^^^^^^^^^^^^^
  File "/home/llmteam/.pyenv/versions/3.11.12/lib/python3.11/site-packages/urllib3/connectionpool.py", line 488, in _make_request
    raise new_e
  File "/home/llmteam/.pyenv/versions/3.11.12/lib/python3.11/site-packages/urllib3/connectionpool.py", line 464, in _make_request
    self._validate_conn(conn)
  File "/home/llmteam/.pyenv/versions/3.11.12/lib/python3.11/site-packages/urllib3/connectionpool.py", line 1093, in _validate_conn
    conn.connect()
  File "/home/llmteam/.pyenv/versions/3.11.12/lib/python3.11/site-packages/urllib3/connection.py", line 753, in connect
    self.sock = sock = self._new_conn()
                       ^^^^^^^^^^^^^^^^
  File "/home/llmteam/.pyenv/versions/3.11.12/lib/python3.11/site-packages/urllib3/connection.py", line 207, in _new_conn
    raise ConnectTimeoutError(
urllib3.exceptions.ConnectTimeoutError: (<urllib3.connection.HTTPSConnection object at 0x7f2d54fe3950>, 'Connection to api.wandb.ai timed out. (connect timeout=20)')

The above exception was the direct cause of the following exception:

Traceback (most recent call last):
  File "/home/llmteam/.pyenv/versions/3.11.12/lib/python3.11/site-packages/requests/adapters.py", line 644, in send
    resp = conn.urlopen(
           ^^^^^^^^^^^^^
  File "/home/llmteam/.pyenv/versions/3.11.12/lib/python3.11/site-packages/urllib3/connectionpool.py", line 841, in urlopen
    retries = retries.increment(
              ^^^^^^^^^^^^^^^^^^
  File "/home/llmteam/.pyenv/versions/3.11.12/lib/python3.11/site-packages/urllib3/util/retry.py", line 519, in increment
    raise MaxRetryError(_pool, url, reason) from reason  # type: ignore[arg-type]
    ^^^^^^^^^^^^^^^^^^^^^^^^^^^^^^^^^^^^^^^^^^^^^^^^^^^
urllib3.exceptions.MaxRetryError: HTTPSConnectionPool(host='api.wandb.ai', port=443): Max retries exceeded with url: /graphql (Caused by ConnectTimeoutError(<urllib3.connection.HTTPSConnection object at 0x7f2d54fe3950>, 'Connection to api.wandb.ai timed out. (connect timeout=20)'))

During handling of the above exception, another exception occurred:

Traceback (most recent call last):
  File "/home/llmteam/.pyenv/versions/3.11.12/lib/python3.11/site-packages/wandb/sdk/lib/retry.py", line 158, in __call__
    result = self._call_fn(*args, **kwargs)
             ^^^^^^^^^^^^^^^^^^^^^^^^^^^^^^
  File "/home/llmteam/.pyenv/versions/3.11.12/lib/python3.11/site-packages/wandb/sdk/internal/internal_api.py", line 398, in execute
    return self.client.execute(*args, **kwargs)  # type: ignore
           ^^^^^^^^^^^^^^^^^^^^^^^^^^^^^^^^^^^^
  File "/home/llmteam/.pyenv/versions/3.11.12/lib/python3.11/site-packages/wandb/vendor/gql-0.2.0/wandb_gql/client.py", line 52, in execute
    result = self._get_result(document, *args, **kwargs)
             ^^^^^^^^^^^^^^^^^^^^^^^^^^^^^^^^^^^^^^^^^^^
  File "/home/llmteam/.pyenv/versions/3.11.12/lib/python3.11/site-packages/wandb/vendor/gql-0.2.0/wandb_gql/client.py", line 60, in _get_result
    return self.transport.execute(document, *args, **kwargs)
           ^^^^^^^^^^^^^^^^^^^^^^^^^^^^^^^^^^^^^^^^^^^^^^^^^
  File "/home/llmteam/.pyenv/versions/3.11.12/lib/python3.11/site-packages/wandb/sdk/lib/gql_request.py", line 58, in execute
    request = self.session.post(self.url, **post_args)
              ^^^^^^^^^^^^^^^^^^^^^^^^^^^^^^^^^^^^^^^^
  File "/home/llmteam/.pyenv/versions/3.11.12/lib/python3.11/site-packages/requests/sessions.py", line 637, in post
    return self.request("POST", url, data=data, json=json, **kwargs)
           ^^^^^^^^^^^^^^^^^^^^^^^^^^^^^^^^^^^^^^^^^^^^^^^^^^^^^^^^^
  File "/home/llmteam/.pyenv/versions/3.11.12/lib/python3.11/site-packages/requests/sessions.py", line 589, in request
    resp = self.send(prep, **send_kwargs)
           ^^^^^^^^^^^^^^^^^^^^^^^^^^^^^^
  File "/home/llmteam/.pyenv/versions/3.11.12/lib/python3.11/site-packages/requests/sessions.py", line 703, in send
    r = adapter.send(request, **kwargs)
        ^^^^^^^^^^^^^^^^^^^^^^^^^^^^^^^
  File "/home/llmteam/.pyenv/versions/3.11.12/lib/python3.11/site-packages/requests/adapters.py", line 665, in send
    raise ConnectTimeout(e, request=request)
requests.exceptions.ConnectTimeout: HTTPSConnectionPool(host='api.wandb.ai', port=443): Max retries exceeded with url: /graphql (Caused by ConnectTimeoutError(<urllib3.connection.HTTPSConnection object at 0x7f2d54fe3950>, 'Connection to api.wandb.ai timed out. (connect timeout=20)'))
